<?xml version="1.0" encoding="utf-8"?>
<!-- This URDF was automatically created by SolidWorks to URDF Exporter! Originally created by Stephen Brawner (brawner@gmail.com) 
     Commit Version: 1.6.0-1-g15f4949  Build Version: 1.6.7594.29634
     For more information, please see http://wiki.ros.org/sw_urdf_exporter -->
<robot
  name="x200-11-03">
  <link
    name="pelvis_link">
    <inertial>
      <origin
        xyz="8.1282E-05 -4.9991E-05 -0.10945"
        rpy="0 0 0" />
      <mass
        value="2.7807" />
      <inertia
        ixx="0.0062726"
        ixy="-3.0602E-07"
        ixz="-1.7253E-06"
        iyy="0.0062958"
        iyz="4.3744E-06"
        izz="0.0037723" />
    </inertial>
    <visual>
      <origin
        xyz="0 0 0"
        rpy="0 0 0" />
      <geometry>
        <mesh
          filename="package://x200-11-03/meshes/pelvis_link.STL" />
      </geometry>
      <material
        name="">
        <color
          rgba="0.75294 0.75294 0.75294 1" />
      </material>
    </visual>
    <collision>
      <origin
        xyz="0 0 0"
        rpy="0 0 0" />
      <geometry>
        <mesh
          filename="package://x200-11-03/meshes/pelvis_link.STL" />
      </geometry>
    </collision>
  </link>
  <link
    name="left_hip_pitch_link">
    <inertial>
      <origin
        xyz="-0.016949 0.07623 0.00040721"
        rpy="0 0 0" />
      <mass
        value="1.4583" />
      <inertia
        ixx="0.0029564"
        ixy="-1.9846E-05"
        ixz="-9.2983E-06"
        iyy="0.0017674"
        iyz="2.4485E-05"
        izz="0.0020892" />
    </inertial>
    <visual>
      <origin
        xyz="0 0 0"
        rpy="0 0 0" />
      <geometry>
        <mesh
          filename="package://x200-11-03/meshes/left_hip_pitch_link.STL" />
      </geometry>
      <material
        name="">
        <color
          rgba="0.75294 0.75294 0.75294 1" />
      </material>
    </visual>
    <collision>
      <origin
        xyz="0 0 0"
        rpy="0 0 0" />
      <geometry>
        <mesh
          filename="package://x200-11-03/meshes/left_hip_pitch_link.STL" />
      </geometry>
    </collision>
  </link>
  <joint
    name="left_hip_pitch_joint"
    type="revolute">
    <origin
      xyz="0 0.0535 -0.1245"
      rpy="0 0 0" />
    <parent
      link="pelvis_link" />
    <child
      link="left_hip_pitch_link" />
    <axis
      xyz="0 1 0" />
    <limit
      lower="-2.5"
      upper="2.5"
      effort="140"
      velocity="37" />
  </joint>
  <link
    name="left_hip_roll_link">
    <inertial>
      <origin
        xyz="0.0035885 0.00042463 -0.082507"
        rpy="0 0 0" />
      <mass
        value="1.9043" />
      <inertia
        ixx="0.0050651"
        ixy="-2.6779E-06"
        ixz="-9.9685E-05"
        iyy="0.0052788"
        iyz="1.863E-05"
        izz="0.0048908" />
    </inertial>
    <visual>
      <origin
        xyz="0 0 0"
        rpy="0 0 0" />
      <geometry>
        <mesh
          filename="package://x200-11-03/meshes/left_hip_roll_link.STL" />
      </geometry>
      <material
        name="">
        <color
          rgba="0.75294 0.75294 0.75294 1" />
      </material>
    </visual>
    <collision>
      <origin
        xyz="0 0 0"
        rpy="0 0 0" />
      <geometry>
        <mesh
          filename="package://x200-11-03/meshes/left_hip_roll_link.STL" />
      </geometry>
    </collision>
  </link>
  <joint
    name="left_hip_roll_joint"
    type="revolute">
    <origin
      xyz="0 0.086 0"
      rpy="0 0 0" />
    <parent
      link="left_hip_pitch_link" />
    <child
      link="left_hip_roll_link" />
    <axis
      xyz="1 0 0" />
    <limit
      lower="-0.4"
      upper="1.45"
      effort="140"
      velocity="37" />
  </joint>
  <link
    name="left_hip_yaw_link">
    <inertial>
      <origin
        xyz="0.0037074 -0.0062686 -0.15994"
        rpy="0 0 0" />
      <mass
        value="2.6495" />
      <inertia
        ixx="0.0067303"
        ixy="-2.959E-05"
        ixz="0.00019268"
        iyy="0.0095452"
        iyz="0.00044058"
        izz="0.0044684" />
    </inertial>
    <visual>
      <origin
        xyz="0 0 0"
        rpy="0 0 0" />
      <geometry>
        <mesh
          filename="package://x200-11-03/meshes/left_hip_yaw_link.STL" />
      </geometry>
      <material
        name="">
        <color
          rgba="0.75294 0.75294 0.75294 1" />
      </material>
    </visual>
    <collision>
      <origin
        xyz="0 0 0"
        rpy="0 0 0" />
      <geometry>
        <mesh
          filename="package://x200-11-03/meshes/left_hip_yaw_link.STL" />
      </geometry>
    </collision>
  </link>
  <joint
    name="left_hip_yaw_joint"
    type="revolute">
    <origin
      xyz="0 0 -0.1355"
      rpy="0 0 0" />
    <parent
      link="left_hip_roll_link" />
    <child
      link="left_hip_yaw_link" />
    <axis
      xyz="0 0 1" />
    <limit
      lower="-2.5"
      upper="2.5"
      effort="140"
      velocity="37" />
  </joint>
  <link
    name="left_knee_link">
    <inertial>
      <origin
        xyz="0.0070649 -0.0013484 -0.13665"
        rpy="0 0 0" />
      <mass
        value="2.8183" />
      <inertia
        ixx="0.016697"
        ixy="2.668E-05"
        ixz="0.00038824"
        iyy="0.015554"
        iyz="-0.0002089"
        izz="0.0034354" />
    </inertial>
    <visual>
      <origin
        xyz="0 0 0"
        rpy="0 0 0" />
      <geometry>
        <mesh
          filename="package://x200-11-03/meshes/left_knee_link.STL" />
      </geometry>
      <material
        name="">
        <color
          rgba="0.75294 0.75294 0.75294 1" />
      </material>
    </visual>
    <collision>
      <origin
        xyz="0 0 0"
        rpy="0 0 0" />
      <geometry>
        <mesh
          filename="package://x200-11-03/meshes/left_knee_link.STL" />
      </geometry>
    </collision>
  </link>
  <joint
    name="left_knee_joint"
    type="revolute">
    <origin
      xyz="0 0 -0.19"
      rpy="0 0 0" />
    <parent
      link="left_hip_yaw_link" />
    <child
      link="left_knee_link" />
    <axis
      xyz="0 1 0" />
    <limit
      lower="-0.02"
      upper="2"
      effort="150"
      velocity="37" />
  </joint>
  <link
    name="left_ankle_pitch_link">
    <inertial>
      <origin
        xyz="-0.00031412 1.918E-07 -0.003667"
        rpy="0 0 0" />
      <mass
        value="0.0722" />
      <inertia
        ixx="1.0544E-05"
        ixy="-2.2759E-12"
        ixz="-4.3816E-07"
        iyy="1.238E-05"
        iyz="1.3059E-18"
        izz="6.3025E-06" />
    </inertial>
    <visual>
      <origin
        xyz="0 0 0"
        rpy="0 0 0" />
      <geometry>
        <mesh
          filename="package://x200-11-03/meshes/left_ankle_pitch_link.STL" />
      </geometry>
      <material
        name="">
        <color
          rgba="0.75294 0.75294 0.75294 1" />
      </material>
    </visual>
    <collision>
      <origin
        xyz="0 0 0"
        rpy="0 0 0" />
      <geometry>
        <mesh
          filename="package://x200-11-03/meshes/left_ankle_pitch_link.STL" />
      </geometry>
    </collision>
  </link>
  <joint
    name="left_ankle_pitch_joint"
    type="revolute">
    <origin
      xyz="0 0 -0.33"
      rpy="0 0 0" />
    <parent
      link="left_knee_link" />
    <child
      link="left_ankle_pitch_link" />
    <axis
      xyz="0 1 0" />
    <limit
      lower="-0.4"
      upper="0.6"
      effort="140"
      velocity="37" />
  </joint>
  <link
    name="left_ankle_roll_link">
    <inertial>
      <origin
        xyz="0.046085 8.3095E-06 -0.015984"
        rpy="0 0 0" />
      <mass
        value="0.6654" />
      <inertia
        ixx="0.00035049"
        ixy="1.0669E-07"
        ixz="1.6968E-05"
        iyy="0.0017849"
        iyz="1.8506E-07"
        izz="0.0020908" />
    </inertial>
    <visual>
      <origin
        xyz="0 0 0"
        rpy="0 0 0" />
      <geometry>
        <mesh
          filename="package://x200-11-03/meshes/left_ankle_roll_link.STL" />
      </geometry>
      <material
        name="">
        <color
          rgba="0.75294 0.75294 0.75294 1" />
      </material>
    </visual>
    <collision>
      <origin
        xyz="0 0 0"
        rpy="0 0 0" />
      <geometry>
        <mesh
          filename="package://x200-11-03/meshes/left_ankle_roll_link.STL" />
      </geometry>
    </collision>
  </link>
  <joint
    name="left_ankle_roll_joint"
    type="revolute">
    <origin
      xyz="0 0 -0.012"
      rpy="0 0 0" />
    <parent
      link="left_ankle_pitch_link" />
    <child
      link="left_ankle_roll_link" />
    <axis
      xyz="1 0 0" />
    <limit
      lower="-0.43"
      upper="0.43"
      effort="140"
      velocity="37" />
  </joint>
  <link
    name="right_hip_pitch_link">
    <inertial>
      <origin
        xyz="-0.016949 -0.076226 0.00041407"
        rpy="0 0 0" />
      <mass
        value="1.4583" />
      <inertia
        ixx="0.0029564"
        ixy="1.9852E-05"
        ixz="-9.2934E-06"
        iyy="0.0017675"
        iyz="-2.4495E-05"
        izz="0.0020891" />
    </inertial>
    <visual>
      <origin
        xyz="0 0 0"
        rpy="0 0 0" />
      <geometry>
        <mesh
          filename="package://x200-11-03/meshes/right_hip_pitch_link.STL" />
      </geometry>
      <material
        name="">
        <color
          rgba="0.75294 0.75294 0.75294 1" />
      </material>
    </visual>
    <collision>
      <origin
        xyz="0 0 0"
        rpy="0 0 0" />
      <geometry>
        <mesh
          filename="package://x200-11-03/meshes/right_hip_pitch_link.STL" />
      </geometry>
    </collision>
  </link>
  <joint
    name="right_hip_pitch_joint"
    type="revolute">
    <origin
      xyz="0 -0.0535 -0.1245"
      rpy="0 0 0" />
    <parent
      link="pelvis_link" />
    <child
      link="right_hip_pitch_link" />
    <axis
      xyz="0 1 0" />
    <limit
      lower="-2.5"
      upper="2.5"
      effort="140"
      velocity="37" />
  </joint>
  <link
    name="right_hip_roll_link">
    <inertial>
      <origin
        xyz="0.0035942 -0.00037394 -0.082486"
        rpy="0 0 0" />
      <mass
        value="1.9043" />
      <inertia
        ixx="0.0050646"
        ixy="2.661E-06"
        ixz="-9.9396E-05"
        iyy="0.0052775"
        iyz="-1.8864E-05"
        izz="0.0048904" />
    </inertial>
    <visual>
      <origin
        xyz="0 0 0"
        rpy="0 0 0" />
      <geometry>
        <mesh
          filename="package://x200-11-03/meshes/right_hip_roll_link.STL" />
      </geometry>
      <material
        name="">
        <color
          rgba="0.75294 0.75294 0.75294 1" />
      </material>
    </visual>
    <collision>
      <origin
        xyz="0 0 0"
        rpy="0 0 0" />
      <geometry>
        <mesh
          filename="package://x200-11-03/meshes/right_hip_roll_link.STL" />
      </geometry>
    </collision>
  </link>
  <joint
    name="right_hip_roll_joint"
    type="revolute">
    <origin
      xyz="0 -0.086 0"
      rpy="0 0 0" />
    <parent
      link="right_hip_pitch_link" />
    <child
      link="right_hip_roll_link" />
    <axis
      xyz="1 0 0" />
    <limit
      lower="-1.45"
      upper="0.4"
      effort="140"
      velocity="37" />
  </joint>
  <link
    name="right_hip_yaw_link">
    <inertial>
      <origin
        xyz="0.0037014 0.0062693 -0.15994"
        rpy="0 0 0" />
      <mass
        value="2.6495" />
      <inertia
        ixx="0.0067296"
        ixy="3.1569E-05"
        ixz="0.00019332"
        iyy="0.0095437"
        iyz="-0.00044057"
        izz="0.0044678" />
    </inertial>
    <visual>
      <origin
        xyz="0 0 0"
        rpy="0 0 0" />
      <geometry>
        <mesh
          filename="package://x200-11-03/meshes/right_hip_yaw_link.STL" />
      </geometry>
      <material
        name="">
        <color
          rgba="0.75294 0.75294 0.75294 1" />
      </material>
    </visual>
    <collision>
      <origin
        xyz="0 0 0"
        rpy="0 0 0" />
      <geometry>
        <mesh
          filename="package://x200-11-03/meshes/right_hip_yaw_link.STL" />
      </geometry>
    </collision>
  </link>
  <joint
    name="right_hip_yaw_joint"
    type="revolute">
    <origin
      xyz="0 0 -0.1355"
      rpy="0 0 0" />
    <parent
      link="right_hip_roll_link" />
    <child
      link="right_hip_yaw_link" />
    <axis
      xyz="0 0 1" />
    <limit
      lower="-2.5"
      upper="2.5"
      effort="140"
      velocity="37" />
  </joint>
  <link
    name="right_knee_link">
    <inertial>
      <origin
        xyz="0.0070641 0.0014446 -0.13675"
        rpy="0 0 0" />
      <mass
        value="2.8183" />
      <inertia
        ixx="0.016695"
        ixy="-2.6547E-05"
        ixz="0.00038813"
        iyy="0.015552"
        iyz="0.00020916"
        izz="0.0034353" />
    </inertial>
    <visual>
      <origin
        xyz="0 0 0"
        rpy="0 0 0" />
      <geometry>
        <mesh
          filename="package://x200-11-03/meshes/right_knee_link.STL" />
      </geometry>
      <material
        name="">
        <color
          rgba="0.75294 0.75294 0.75294 1" />
      </material>
    </visual>
    <collision>
      <origin
        xyz="0 0 0"
        rpy="0 0 0" />
      <geometry>
        <mesh
          filename="package://x200-11-03/meshes/right_knee_link.STL" />
      </geometry>
    </collision>
  </link>
  <joint
    name="right_knee_joint"
    type="revolute">
    <origin
      xyz="0 0 -0.19"
      rpy="0 0 0" />
    <parent
      link="right_hip_yaw_link" />
    <child
      link="right_knee_link" />
    <axis
      xyz="0 1 0" />
    <limit
      lower="-0.02"
      upper="2"
      effort="150"
      velocity="37" />
  </joint>
  <link
    name="right_ankle_pitch_link">
    <inertial>
      <origin
        xyz="-0.00032568 5.799E-09 -0.0036651"
        rpy="0 0 0" />
      <mass
        value="0.0722" />
      <inertia
        ixx="1.0544E-05"
        ixy="-2.1968E-10"
        ixz="-4.3815E-07"
        iyy="1.238E-05"
        iyz="1.0414E-10"
        izz="6.3025E-06" />
    </inertial>
    <visual>
      <origin
        xyz="0 0 0"
        rpy="0 0 0" />
      <geometry>
        <mesh
          filename="package://x200-11-03/meshes/right_ankle_pitch_link.STL" />
      </geometry>
      <material
        name="">
        <color
          rgba="0.75294 0.75294 0.75294 1" />
      </material>
    </visual>
    <collision>
      <origin
        xyz="0 0 0"
        rpy="0 0 0" />
      <geometry>
        <mesh
          filename="package://x200-11-03/meshes/right_ankle_pitch_link.STL" />
      </geometry>
    </collision>
  </link>
  <joint
    name="right_ankle_pitch_joint"
    type="revolute">
    <origin
      xyz="0 0 -0.33"
      rpy="0 0 0" />
    <parent
      link="right_knee_link" />
    <child
      link="right_ankle_pitch_link" />
    <axis
      xyz="0 1 0" />
    <limit
      lower="-0.4"
      upper="0.6"
      effort="140"
      velocity="37" />
  </joint>
  <link
    name="right_ankle_roll_link">
    <inertial>
      <origin
        xyz="0.046084 -6.2872E-05 -0.015969"
        rpy="0 0 0" />
      <mass
        value="0.6654" />
      <inertia
        ixx="0.0003505"
        ixy="-1.8613E-06"
        ixz="1.6896E-05"
        iyy="0.001785"
        iyz="-2.0899E-07"
        izz="0.0020909" />
    </inertial>
    <visual>
      <origin
        xyz="0 0 0"
        rpy="0 0 0" />
      <geometry>
        <mesh
          filename="package://x200-11-03/meshes/right_ankle_roll_link.STL" />
      </geometry>
      <material
        name="">
        <color
          rgba="0.75294 0.75294 0.75294 1" />
      </material>
    </visual>
    <collision>
      <origin
        xyz="0 0 0"
        rpy="0 0 0" />
      <geometry>
        <mesh
          filename="package://x200-11-03/meshes/right_ankle_roll_link.STL" />
      </geometry>
    </collision>
  </link>
  <joint
    name="right_ankle_roll_joint"
    type="revolute">
    <origin
      xyz="0 0 -0.011998"
      rpy="0 0 0" />
    <parent
      link="right_ankle_pitch_link" />
    <child
      link="right_ankle_roll_link" />
    <axis
      xyz="1 0 0" />
    <limit
      lower="-0.43"
      upper="0.43"
      effort="140"
      velocity="37" />
  </joint>
  <link
    name="torso_link">
    <inertial>
      <origin
        xyz="0.0012343716878745 0.000371429896273605 0.227654072484662"
        rpy="0 0 0" />
      <mass
        value="9.23222404839966" />
      <inertia
        ixx="0.0534044121661209"
        ixy="-3.47134212365044E-05"
        ixz="-0.000187457543130805"
        iyy="0.0440234160973352"
        iyz="0.000639323006480399"
        izz="0.020784425156714" />
    </inertial>
    <!-- <visual>
      <origin
        xyz="0 0 0"
        rpy="0 0 0" />
      <geometry>
        <mesh
          filename="package://x200-11-03/meshes/torso_link.STL" />
      </geometry>
      <material
        name="">
        <color
          rgba="0.752941176470588 0.752941176470588 0.752941176470588 1" />
      </material>
    </visual> -->
    <collision>
      <origin
        xyz="0 0 0"
        rpy="0 0 0" />
      <geometry>
        <mesh
          filename="package://x200-11-03/meshes/torso_link.STL" />
      </geometry>
    </collision>
  </link>
  <joint
    name="torso_joint"
    type="revolute">
    <origin
      xyz="0 0 0"
      rpy="0 0 0" />
    <parent
      link="pelvis_link" />
    <child
      link="torso_link" />
    <axis
      xyz="0 0 1" />
    <limit
      lower="-2.55"
      upper="2.55"
      effort="100"
      velocity="37" />
  </joint>
  <link
    name="left_shoulder_pitch_link">
    <inertial>
      <origin
        xyz="-0.00090501 0.031209 0.0053949"
        rpy="0 0 0" />
      <mass
        value="0.6775" />
      <inertia
        ixx="0.0015231"
        ixy="-7.6096E-06"
        ixz="1.0752E-06"
        iyy="0.0025478"
        iyz="6.0803E-05"
        izz="0.0020658" />
    </inertial>
    <visual>
      <origin
        xyz="0 0 0"
        rpy="0 0 0" />
      <geometry>
        <mesh
          filename="package://x200-11-03/meshes/left_shoulder_pitch_link.STL" />
      </geometry>
      <material
        name="">
        <color
          rgba="0.75294 0.75294 0.75294 1" />
      </material>
    </visual>
    <collision>
      <origin
        xyz="0 0 0"
        rpy="0 0 0" />
      <geometry>
        <mesh
          filename="package://x200-11-03/meshes/left_shoulder_pitch_link.STL" />
      </geometry>
    </collision>
  </link>
  <joint
    name="left_shoulder_pitch_joint"
    type="revolute">
    <origin
      xyz="0 0.1235 0.333"
      rpy="0 0 0" />
    <parent
      link="torso_link" />
    <child
      link="left_shoulder_pitch_link" />
    <axis
      xyz="0 1 0" />
    <limit
      lower="-2.8"
      upper="2.8"
      effort="60"
      velocity="37" />
  </joint>
  <link
    name="left_shoulder_roll_link">
    <inertial>
      <origin
        xyz="0.0093001 -0.0011844 -0.009774"
        rpy="0 0 0" />
      <mass
        value="1.4117" />
      <inertia
        ixx="0.0027272"
        ixy="6.6259E-06"
        ixz="1.46E-05"
        iyy="0.0020079"
        iyz="-0.00012636"
        izz="0.0017257" />
    </inertial>
    <visual>
      <origin
        xyz="0 0 0"
        rpy="0 0 0" />
      <geometry>
        <mesh
          filename="package://x200-11-03/meshes/left_shoulder_roll_link.STL" />
      </geometry>
      <material
        name="">
        <color
          rgba="0.75294 0.75294 0.75294 1" />
      </material>
    </visual>
    <collision>
      <origin
        xyz="0 0 0"
        rpy="0 0 0" />
      <geometry>
        <mesh
          filename="package://x200-11-03/meshes/left_shoulder_roll_link.STL" />
      </geometry>
    </collision>
  </link>
  <joint
    name="left_shoulder_roll_joint"
    type="revolute">
    <origin
      xyz="0 0.065 0"
      rpy="0 0 0" />
    <parent
      link="left_shoulder_pitch_link" />
    <child
      link="left_shoulder_roll_link" />
    <axis
      xyz="1 0 0" />
    <limit
      lower="-0.03"
      upper="2.1"
      effort="60"
      velocity="37" />
  </joint>
  <link
    name="left_shoulder_yaw_link">
    <inertial>
      <origin
        xyz="-0.0022587 0.00061632 -0.054042"
        rpy="0 0 0" />
      <mass
        value="1.1502" />
      <inertia
        ixx="0.0020304"
        ixy="-1.0169E-06"
        ixz="3.1867E-05"
        iyy="0.0017671"
        iyz="2.4218E-05"
        izz="0.0016535" />
    </inertial>
    <visual>
      <origin
        xyz="0 0 0"
        rpy="0 0 0" />
      <geometry>
        <mesh
          filename="package://x200-11-03/meshes/left_shoulder_yaw_link.STL" />
      </geometry>
      <material
        name="">
        <color
          rgba="0.75294 0.75294 0.75294 1" />
      </material>
    </visual>
    <collision>
      <origin
        xyz="0 0 0"
        rpy="0 0 0" />
      <geometry>
        <mesh
          filename="package://x200-11-03/meshes/left_shoulder_yaw_link.STL" />
      </geometry>
    </collision>
  </link>
  <joint
    name="left_shoulder_yaw_joint"
    type="revolute">
    <origin
      xyz="0 0 -0.0955"
      rpy="0 0 0" />
    <parent
      link="left_shoulder_roll_link" />
    <child
      link="left_shoulder_yaw_link" />
    <axis
      xyz="0 0 1" />
    <limit
      lower="-2.8"
      upper="2.8"
      effort="60"
      velocity="37" />
  </joint>
  <link
    name="left_elbow_link">
    <inertial>
      <origin
        xyz="0.031159 0.0053326 6.435E-05"
        rpy="0 0 0" />
      <mass
        value="1.2549" />
      <inertia
        ixx="0.00083742"
        ixy="-3.0509E-05"
        ixz="2.7009E-06"
        iyy="0.0013448"
        iyz="3.5957E-07"
        izz="0.0010635" />
    </inertial>
    <visual>
      <origin
        xyz="0 0 0"
        rpy="0 0 0" />
      <geometry>
        <mesh
          filename="package://x200-11-03/meshes/left_elbow_link.STL" />
      </geometry>
      <material
        name="">
        <color
          rgba="0.75294 0.75294 0.75294 1" />
      </material>
    </visual>
    <collision>
      <origin
        xyz="0 0 0"
        rpy="0 0 0" />
      <geometry>
        <mesh
          filename="package://x200-11-03/meshes/left_elbow_link.STL" />
      </geometry>
    </collision>
  </link>
  <joint
    name="left_elbow_joint"
    type="revolute">
    <origin
      xyz="0 0 -0.1255"
      rpy="0 0 0" />
    <parent
      link="left_shoulder_yaw_link" />
    <child
      link="left_elbow_link" />
    <axis
      xyz="0 1 0" />
    <limit
      lower="-0.55"
      upper="1.55"
      effort="60"
      velocity="37" />
  </joint>
  <link
    name="left_wrist_roll_link">
    <inertial>
      <origin
        xyz="0.062819 6.9392E-05 -5.408E-07"
        rpy="0 0 0" />
      <mass
        value="0.2374" />
      <inertia
        ixx="0.00017373"
        ixy="-3.9811E-07"
        ixz="-1.9174E-11"
        iyy="0.00032606"
        iyz="-1.8326E-09"
        izz="0.00032579" />
    </inertial>
    <visual>
      <origin
        xyz="0 0 0"
        rpy="0 0 0" />
      <geometry>
        <mesh
          filename="package://x200-11-03/meshes/left_wrist_roll_link.STL" />
      </geometry>
      <material
        name="">
        <color
          rgba="0.75294 0.75294 0.75294 1" />
      </material>
    </visual>
    <collision>
      <origin
        xyz="0 0 0"
        rpy="0 0 0" />
      <geometry>
        <mesh
          filename="package://x200-11-03/meshes/left_wrist_roll_link.STL" />
      </geometry>
    </collision>
  </link>
  <joint
    name="left_wrist_roll_joint"
    type="revolute">
    <origin
      xyz="0.109 0 0"
      rpy="0 0 0" />
    <parent
      link="left_elbow_link" />
    <child
      link="left_wrist_roll_link" />
    <axis
      xyz="1 0 0" />
    <limit
      lower="-2.8"
      upper="2.8"
      effort="60"
      velocity="37" />
  </joint>
  <link
    name="left_hand_base_link">
    <inertial>
      <origin
        xyz="0.01345 6.8699E-08 1.2296E-08"
        rpy="0 0 0" />
      <mass
        value="0.0673" />
      <inertia
        ixx="2.7956E-05"
        ixy="-5.9188E-11"
        ixz="-1.0594E-11"
        iyy="1.6367E-05"
        iyz="-5.4107E-17"
        izz="1.6367E-05" />
    </inertial>
    <visual>
      <origin
        xyz="0 0 0"
        rpy="0 0 0" />
      <geometry>
        <mesh
          filename="package://x200-11-03/meshes/left_hand_base_link.STL" />
      </geometry>
      <material
        name="">
        <color
          rgba="0.75294 0.75294 0.75294 1" />
      </material>
    </visual>
    <collision>
      <origin
        xyz="0 0 0"
        rpy="0 0 0" />
      <geometry>
        <mesh
          filename="package://x200-11-03/meshes/left_hand_base_link.STL" />
      </geometry>
    </collision>
  </link>
  <joint
    name="left_hand_base_joint"
    type="fixed">
    <origin
      xyz="0.1365 0 0"
      rpy="0 0 0" />
    <parent
      link="left_wrist_roll_link" />
    <child
      link="left_hand_base_link" />
    <axis
      xyz="0 0 0" />
  </joint>
  <link
    name="right_shoulder_pitch_link">
    <inertial>
      <origin
        xyz="-0.00090326 -0.031179 0.0054049"
        rpy="0 0 0" />
      <mass
        value="0.6775" />
      <inertia
        ixx="0.0015229"
        ixy="7.3996E-06"
        ixz="1.1258E-06"
        iyy="0.0025479"
        iyz="-6.1086E-05"
        izz="0.0020657" />
    </inertial>
    <visual>
      <origin
        xyz="0 0 0"
        rpy="0 0 0" />
      <geometry>
        <mesh
          filename="package://x200-11-03/meshes/right_shoulder_pitch_link.STL" />
      </geometry>
      <material
        name="">
        <color
          rgba="0.75294 0.75294 0.75294 1" />
      </material>
    </visual>
    <collision>
      <origin
        xyz="0 0 0"
        rpy="0 0 0" />
      <geometry>
        <mesh
          filename="package://x200-11-03/meshes/right_shoulder_pitch_link.STL" />
      </geometry>
    </collision>
  </link>
  <joint
    name="right_shoulder_pitch_joint"
    type="revolute">
    <origin
      xyz="0 -0.1235 0.333"
      rpy="0 0 0" />
    <parent
      link="torso_link" />
    <child
      link="right_shoulder_pitch_link" />
    <axis
      xyz="0 1 0" />
    <limit
      lower="-2.8"
      upper="2.8"
      effort="60"
      velocity="37" />
  </joint>
  <link
    name="right_shoulder_roll_link">
    <inertial>
      <origin
        xyz="0.0093059 0.0012133 -0.0098174"
        rpy="0 0 0" />
      <mass
        value="1.4117" />
      <inertia
        ixx="0.0027274"
        ixy="-6.4394E-06"
        ixz="1.4374E-05"
        iyy="0.0020078"
        iyz="0.00012635"
        izz="0.0017256" />
    </inertial>
    <visual>
      <origin
        xyz="0 0 0"
        rpy="0 0 0" />
      <geometry>
        <mesh
          filename="package://x200-11-03/meshes/right_shoulder_roll_link.STL" />
      </geometry>
      <material
        name="">
        <color
          rgba="0.75294 0.75294 0.75294 1" />
      </material>
    </visual>
    <collision>
      <origin
        xyz="0 0 0"
        rpy="0 0 0" />
      <geometry>
        <mesh
          filename="package://x200-11-03/meshes/right_shoulder_roll_link.STL" />
      </geometry>
    </collision>
  </link>
  <joint
    name="right_shoulder_roll_joint"
    type="revolute">
    <origin
      xyz="0 -0.065 0"
      rpy="0 0 0" />
    <parent
      link="right_shoulder_pitch_link" />
    <child
      link="right_shoulder_roll_link" />
    <axis
      xyz="1 0 0" />
    <limit
      lower="-2.1"
      upper="0.03"
      effort="60"
      velocity="37" />
  </joint>
  <link
    name="right_shoulder_yaw_link">
    <inertial>
      <origin
        xyz="-0.0024827 -0.00067862 -0.054051"
        rpy="0 0 0" />
      <mass
        value="1.1502" />
      <inertia
        ixx="0.0020334"
        ixy="5.7205E-06"
        ixz="3.1782E-05"
        iyy="0.0017644"
        iyz="-2.4274E-05"
        izz="0.0016535" />
    </inertial>
    <visual>
      <origin
        xyz="0 0 0"
        rpy="0 0 0" />
      <geometry>
        <mesh
          filename="package://x200-11-03/meshes/right_shoulder_yaw_link.STL" />
      </geometry>
      <material
        name="">
        <color
          rgba="0.75294 0.75294 0.75294 1" />
      </material>
    </visual>
    <collision>
      <origin
        xyz="0 0 0"
        rpy="0 0 0" />
      <geometry>
        <mesh
          filename="package://x200-11-03/meshes/right_shoulder_yaw_link.STL" />
      </geometry>
    </collision>
  </link>
  <joint
    name="right_shoulder_yaw_joint"
    type="revolute">
    <origin
      xyz="0 0 -0.0955"
      rpy="0 0 0" />
    <parent
      link="right_shoulder_roll_link" />
    <child
      link="right_shoulder_yaw_link" />
    <axis
      xyz="0 0 1" />
    <limit
      lower="-2.8"
      upper="2.8"
      effort="60"
      velocity="37" />
  </joint>
  <link
    name="right_elbow_link">
    <inertial>
      <origin
        xyz="0.031161 -0.0052786 -0.00015817"
        rpy="0 0 0" />
      <mass
        value="1.2549" />
      <inertia
        ixx="0.00083741"
        ixy="3.0484E-05"
        ixz="-2.7317E-06"
        iyy="0.0013448"
        iyz="4.3532E-07"
        izz="0.0010633" />
    </inertial>
    <visual>
      <origin
        xyz="0 0 0"
        rpy="0 0 0" />
      <geometry>
        <mesh
          filename="package://x200-11-03/meshes/right_elbow_link.STL" />
      </geometry>
      <material
        name="">
        <color
          rgba="0.75294 0.75294 0.75294 1" />
      </material>
    </visual>
    <collision>
      <origin
        xyz="0 0 0"
        rpy="0 0 0" />
      <geometry>
        <mesh
          filename="package://x200-11-03/meshes/right_elbow_link.STL" />
      </geometry>
    </collision>
  </link>
  <joint
    name="right_elbow_joint"
    type="revolute">
    <origin
      xyz="0 0 -0.1255"
      rpy="0 0 0" />
    <parent
      link="right_shoulder_yaw_link" />
    <child
      link="right_elbow_link" />
    <axis
      xyz="0 1 0" />
    <limit
      lower="-0.55"
      upper="1.55"
      effort="60"
      velocity="37" />
  </joint>
  <link
    name="right_wrist_roll_link">
    <inertial>
      <origin
        xyz="0.062819 1.5779E-06 4.7222E-07"
        rpy="0 0 0" />
      <mass
        value="0.2374" />
      <inertia
        ixx="0.00017373"
        ixy="4.606E-07"
        ixz="-5.6797E-08"
        iyy="0.00032606"
        iyz="3.2115E-08"
        izz="0.00032579" />
    </inertial>
    <visual>
      <origin
        xyz="0 0 0"
        rpy="0 0 0" />
      <geometry>
        <mesh
          filename="package://x200-11-03/meshes/right_wrist_roll_link.STL" />
      </geometry>
      <material
        name="">
        <color
          rgba="0.75294 0.75294 0.75294 1" />
      </material>
    </visual>
    <collision>
      <origin
        xyz="0 0 0"
        rpy="0 0 0" />
      <geometry>
        <mesh
          filename="package://x200-11-03/meshes/right_wrist_roll_link.STL" />
      </geometry>
    </collision>
  </link>
  <joint
    name="right_wrist_roll_joint"
    type="revolute">
    <origin
      xyz="0.109 0 0"
      rpy="0 0 0" />
    <parent
      link="right_elbow_link" />
    <child
      link="right_wrist_roll_link" />
    <axis
      xyz="1 0 0" />
    <limit
      lower="-2.8"
      upper="2.8"
      effort="60"
      velocity="37" />
  </joint>
  <link
    name="right_hand_base_link">
    <inertial>
      <origin
        xyz="0.01345 0 1.7347E-18"
        rpy="0 0 0" />
      <mass
        value="0.0673" />
      <inertia
        ixx="2.7956E-05"
        ixy="-2.1385E-21"
        ixz="1.4278E-22"
        iyy="1.6367E-05"
        iyz="1.4168E-21"
        izz="1.6367E-05" />
    </inertial>
    <visual>
      <origin
        xyz="0 0 0"
        rpy="0 0 0" />
      <geometry>
        <mesh
          filename="package://x200-11-03/meshes/right_hand_base_link.STL" />
      </geometry>
      <material
        name="">
        <color
          rgba="0.75294 0.75294 0.75294 1" />
      </material>
    </visual>
    <collision>
      <origin
        xyz="0 0 0"
        rpy="0 0 0" />
      <geometry>
        <mesh
          filename="package://x200-11-03/meshes/right_hand_base_link.STL" />
      </geometry>
    </collision>
  </link>
  <joint
    name="right_hand_base_joint"
    type="fixed">
    <origin
      xyz="0.1365 0 0"
      rpy="0 0 0" />
    <parent
      link="right_wrist_roll_link" />
    <child
      link="right_hand_base_link" />
    <axis
      xyz="0 0 0" />
  </joint>

  <link
    name="d435_link">
    <visual>
      <origin
        xyz="0 0 0"
        rpy="0 0 0" />
      <geometry>
        <box size="0.02 0.07 0.02"/>
      </geometry>
      <material
        name="">
        <color
          rgba="0.75294 0.75294 0.75294 1" />
      </material>
    </visual>


  </link>

  <joint name="d435_joint" type="fixed">
    <origin xyz="0.126235 0.00 0.45987" rpy="0 1.2307767239493009 0"/>
    <parent link="torso_link"/>
    <child link="d435_link"/>
  </joint>

  <!-- <joint
    name="d435_joint"
    type="fixed">
    <origin
      xyz="0 0 0"
      rpy="0 0 0" />
    <parent
      link="torso_link" />
    <child
      link="d435_link" />
    <axis
      xyz="0 0 0" />
  </joint> -->


  <link
    name="head_link">
    <inertial>
      <origin
        xyz="0.021827 -2.8316E-05 0.16022"
        rpy="0 0 0" />
      <mass
        value="0.9776" />
      <inertia
        ixx="0.0025419"
        ixy="-3.9956E-07"
        ixz="-0.00061604"
        iyy="0.0026721"
        iyz="5.776E-07"
        izz="0.0015009" />
    </inertial>
    <visual>
      <origin
        xyz="0 0 0"
        rpy="0 0 0" />
      <geometry>
        <mesh
          filename="package://x200-11-03/meshes/head_link.STL" />
      </geometry>
      <material
        name="">
        <color
          rgba="0.75294 0.75294 0.75294 1" />
      </material>
    </visual>
    <collision>
      <origin
        xyz="0 0 0"
        rpy="0 0 0" />
      <geometry>
        <mesh
          filename="package://x200-11-03/meshes/head_link.STL" />
      </geometry>
    </collision>
  </link>
  <joint
    name="head_joint"
    type="fixed">
    <origin
      xyz="0 0 0.388"
      rpy="0 0 0" />
    <parent
      link="torso_link" />
    <child
      link="head_link" />
    <axis
      xyz="0 0 0" />
  </joint>
  <link
    name="neck_link">
    <inertial>
      <origin
        xyz="-0.00013121 -0.00088375 -0.034492"
        rpy="0 0 0" />
      <mass
        value="0.9891" />
      <inertia
        ixx="0.00091809"
        ixy="6.925E-06"
        ixz="5.2428E-07"
        iyy="0.00084586"
        iyz="-5.7804E-08"
        izz="0.0016497" />
    </inertial>
    <visual>
      <origin
        xyz="0 0 0"
        rpy="0 0 0" />
      <geometry>
        <mesh
          filename="package://x200-11-03/meshes/neck_link.STL" />
      </geometry>
      <material
        name="">
        <color
          rgba="0.75294 0.75294 0.75294 1" />
      </material>
    </visual>
    <collision>
      <origin
        xyz="0 0 0"
        rpy="0 0 0" />
      <geometry>
        <mesh
          filename="package://x200-11-03/meshes/neck_link.STL" />
      </geometry>
    </collision>
  </link>
  <joint
    name="neck_joint"
    type="fixed">
    <origin
      xyz="0 0 0.051"
      rpy="0 0 0" />
    <parent
      link="torso_link" />
    <child
      link="neck_link" />
    <axis
      xyz="0 0 0" />
  </joint>
  <link
    name="imu_in_pelvis_link">
    <inertial>
      <origin
        xyz="-0.00092676 7.1813E-06 0.0044789"
        rpy="0 0 0" />
      <mass
        value="0.012" />
      <inertia
        ixx="5.7273E-07"
        ixy="1.0857E-14"
        ixz="1.5643E-08"
        iyy="5.3515E-07"
        iyz="-4.5199E-15"
        izz="9.5518E-07" />
    </inertial>
    <visual>
      <origin
        xyz="0 0 0"
        rpy="0 0 0" />
      <geometry>
        <mesh
          filename="package://x200-11-03/meshes/imu_in_pelvis_link.STL" />
      </geometry>
      <material
        name="">
        <color
          rgba="0.86275 0.54902 0.5451 1" />
      </material>
    </visual>
    <collision>
      <origin
        xyz="0 0 0"
        rpy="0 0 0" />
      <geometry>
        <mesh
          filename="package://x200-11-03/meshes/imu_in_pelvis_link.STL" />
      </geometry>
    </collision>
  </link>
  <joint
    name="imu_in_pelvis_joint"
    type="fixed">
    <origin
      xyz="0 0 -0.021"
      rpy="0 0 0" />
    <parent
      link="pelvis_link" />
    <child
      link="imu_in_pelvis_link" />
    <axis
      xyz="0 0 0" />
  </joint>


<!-- 右手 -->
 <link
    name="r_hand_base_link">
    <inertial>
      <origin
        xyz="0.00160320773490556 -0.0538002704027215 -0.000358462699237558"
        rpy="0 0 0" />
      <mass
        value="0.06740077960995" />
      <inertia
        ixx="5.22359941041901E-05"
        ixy="3.88322215371643E-07"
        ixz="3.0391535852764E-07"
        iyy="2.28342677422006E-05"
        iyz="-7.77555280794861E-07"
        izz="3.33473043513648E-05" />
    </inertial>
    <visual>
      <origin
        xyz="0 0 0"
        rpy="-1.5707963267948966 0 3.141592653589793" />
      <geometry>
        <mesh
          filename="package://x200-11-03/right_hand_meshes/r_hand_base_link.STL" />
      </geometry>
      <material
        name="">
        <color
          rgba="1 0.6 0 1" />
      </material>
    </visual>
    <collision>
      <origin
        xyz="0 0 0"
        rpy="-1.5707963267948966 0 3.141592653589793" />
      <geometry>
        <mesh
          filename="package://x200-11-03/right_hand_meshes/r_hand_base_link.STL" />
      </geometry>
    </collision>
  </link>
  <link
    name="r_thumb_metacarpals_base2">
    <inertial>
      <origin
        xyz="0.00162795738393507 0.00276671978336815 -0.00184227725602707"
        rpy="0 0 0" />
      <mass
        value="0.00138591070212997" />
      <inertia
        ixx="5.26294625624223E-08"
        ixy="-3.9288013799604E-09"
        ixz="2.43766268199571E-09"
        iyy="4.82623724532942E-08"
        iyz="3.71867754115443E-09"
        izz="2.88555522060562E-08" />
    </inertial>
    <visual>
      <origin
        xyz="0 0 0"
        rpy="0 0 0" />
      <geometry>
        <mesh
          filename="package://x200-11-03/right_hand_meshes/thumb_metacarpals_base2.STL" />
      </geometry>
      <material
        name="">
        <color
          rgba="0.164705882352941 0.282352941176471 0.443137254901961 1" />
      </material>
    </visual>
    <collision>
      <origin
        xyz="0 0 0"
        rpy="0 0 0" />
      <geometry>
        <mesh
          filename="package://x200-11-03/right_hand_meshes/thumb_metacarpals_base2.STL" />
      </geometry>
    </collision>
  </link>
  <joint
    name="r_thumb_cmc_yaw"
    type="revolute">
    <origin
      xyz="-0.011508 -0.032794 -0.022975"
      rpy="-1.5707963267948966 0 3.141592653589793" />
    <parent
      link="r_hand_base_link" />
    <child
      link="r_thumb_metacarpals_base2" />
    <axis
      xyz="0 0 -1" />
    <limit
      lower="0"
      upper="1.54"
      effort="100"
      velocity="12" />
  </joint>
  <link
    name="r_thumb_metacarpals">
    <inertial>
      <origin
        xyz="4.24920612856275E-05 -1.67885666835232E-05 0.0228341522590467"
        rpy="0 0 0" />
      <mass
        value="0.0123381607727595" />
      <inertia
        ixx="1.10292488693766E-06"
        ixy="-6.14241939151719E-10"
        ixz="1.14233108676795E-07"
        iyy="1.76757658485787E-06"
        iyz="-4.24576599367025E-10"
        izz="9.36348143657406E-07" />
    </inertial>
    <visual>
      <origin
        xyz="0 0 0"
        rpy="0 0 0" />
      <geometry>
        <mesh
          filename="package://x200-11-03/right_hand_meshes/thumb_metacarpals.STL" />
      </geometry>
      <material
        name="">
        <color
          rgba="1 0.6 0 1" />
      </material>
    </visual>
    <collision>
      <origin
        xyz="0 0 0"
        rpy="0 0 0" />
      <geometry>
        <mesh
          filename="package://x200-11-03/right_hand_meshes/thumb_metacarpals.STL" />
      </geometry>
    </collision>
  </link>
  <joint
    name="r_thumb_cmc_pitch"
    type="revolute">
    <origin
      xyz="0.0061649 0.010678 -0.004891"
      rpy="0 -1.1529 -2.0944" />
    <parent
      link="r_thumb_metacarpals_base2" />
    <child
      link="r_thumb_metacarpals" />
    <axis
      xyz="0 1 0" />
    <limit
      lower="0"
      upper="0.52"
      effort="100"
      velocity="12" />
  </joint>
  <link
    name="r_thumb_distal">
    <inertial>
      <origin
        xyz="-0.00413690727496815 -4.54842793429222E-07 0.0230097179163771"
        rpy="0 0 0" />
      <mass
        value="0.00763302603723749" />
      <inertia
        ixx="1.30546842791578E-06"
        ixy="-2.61617511029467E-12"
        ixz="7.19030685242407E-08"
        iyy="1.22457212713176E-06"
        iyz="1.66931068485225E-11"
        izz="2.7729897944409E-07" />
    </inertial>
    <visual>
      <origin
        xyz="0 0 0"
        rpy="0 0 0" />
      <geometry>
        <mesh
          filename="package://x200-11-03/right_hand_meshes/thumb_distal.STL" />
      </geometry>
      <material
        name="">
        <color
          rgba="0.792156862745098 0.792156862745098 0.792156862745098 1" />
      </material>
    </visual>
    <collision>
      <origin
        xyz="0 0 0"
        rpy="0 0 0" />
      <geometry>
        <mesh
          filename="package://x200-11-03/right_hand_meshes/thumb_distal.STL" />
      </geometry>
    </collision>
  </link>
  <joint
    name="r_thumb_ip"
    type="revolute">
    <origin
      xyz="0.0037776 0 0.045368"
      rpy="0 0 0" />
    <parent
      link="r_thumb_metacarpals" />
    <child
      link="r_thumb_distal" />
    <axis
      xyz="0 1 0" />
    <limit
      lower="0"
      upper="0.96"
      effort="100"
      velocity="12" />
    <mimic
      joint="r_thumb_cmc_pitch"
      multiplier="1.83"
      offset="0" />
  </joint>
  <link
    name="r_index_proximal">
    <inertial>
      <origin
        xyz="-0.00208665596033792 -4.8964990644329E-06 0.0172736718900068"
        rpy="0 0 0" />
      <mass
        value="0.00253178529301663" />
      <inertia
        ixx="2.65990159539482E-07"
        ixy="-3.55165625722842E-11"
        ixz="4.31046335852167E-08"
        iyy="2.72915460277804E-07"
        iyz="1.75935978708959E-10"
        izz="8.56026306687528E-08" />
    </inertial>
    <visual>
      <origin
        xyz="0 0 0"
        rpy="0 0 0" />
      <geometry>
        <mesh
          filename="package://x200-11-03/right_hand_meshes/index_proximal.STL" />
      </geometry>
      <material
        name="">
        <color
          rgba="0.980392156862745 0.780392156862745 0.627450980392157 1" />
      </material>
    </visual>
    <collision>
      <origin
        xyz="0 0 0"
        rpy="0 0 0" />
      <geometry>
        <mesh
          filename="package://x200-11-03/right_hand_meshes/index_proximal.STL" />
      </geometry>
    </collision>
  </link>
  <joint
    name="r_index_mcp_pitch"
    type="revolute">
    <origin
      xyz="-0.0024758 -0.098779 -0.02419"
      rpy="-1.6231563267948966 0 3.141592653589793" />
    <parent
      link="r_hand_base_link" />
    <child
      link="r_index_proximal" />
    <axis
      xyz="0 1 0" />
    <limit
      lower="0"
      upper="1.57"
      effort="100"
      velocity="12" />
  </joint>
  <link
    name="r_index_distal">
    <inertial>
      <origin
        xyz="0.00658940011630532 -4.59976557022623E-06 0.0194434136420913"
        rpy="0 0 0" />
      <mass
        value="0.00376787129082313" />
      <inertia
        ixx="3.22116619426455E-07"
        ixy="1.03152735699049E-11"
        ixz="-1.14363506430985E-07"
        iyy="3.65131844686317E-07"
        iyz="-1.97263639269362E-10"
        izz="1.24256890612907E-07" />
    </inertial>
    <visual>
      <origin
        xyz="0 0 0"
        rpy="0 0 0" />
      <geometry>
        <mesh
          filename="package://x200-11-03/right_hand_meshes/index_distal.STL" />
      </geometry>
      <material
        name="">
        <color
          rgba="0.164705882352941 0.282352941176471 0.443137254901961 1" />
      </material>
    </visual>
    <collision>
      <origin
        xyz="0 0 0"
        rpy="0 0 0" />
      <geometry>
        <mesh
          filename="package://x200-11-03/right_hand_meshes/index_distal.STL" />
      </geometry>
    </collision>
  </link>
  <joint
    name="r_index_dip"
    type="revolute">
    <origin
      xyz="-0.0052516 0 0.036625"
      rpy="0 0 0" />
    <parent
      link="r_index_proximal" />
    <child
      link="r_index_distal" />
    <axis
      xyz="0 1 0" />
    <limit
      lower="0"
      upper="1.4"
      effort="100"
      velocity="12" />
    <mimic
      joint="r_index_mcp_pitch"
      multiplier="0.89"
      offset="0" />
  </joint>
  <link
    name="r_middle_proximal">
    <inertial>
      <origin
        xyz="-0.00208661081773556 -4.93451838476378E-06 0.0172736805321904"
        rpy="0 0 0" />
      <mass
        value="0.00253175497594429" />
      <inertia
        ixx="2.65989683690695E-07"
        ixy="-3.58343951791586E-11"
        ixz="4.31048601085216E-08"
        iyy="2.72915006047006E-07"
        iyz="1.75718024412593E-10"
        izz="8.56020467202518E-08" />
    </inertial>
    <visual>
      <origin
        xyz="0 0 0"
        rpy="0 0 0" />
      <geometry>
        <mesh
          filename="package://x200-11-03/right_hand_meshes/middle_proximal.STL" />
      </geometry>
      <material
        name="">
        <color
          rgba="0.164705882352941 0.282352941176471 0.443137254901961 1" />
      </material>
    </visual>
    <collision>
      <origin
        xyz="0 0 0"
        rpy="0 0 0" />
      <geometry>
        <mesh
          filename="package://x200-11-03/right_hand_meshes/middle_proximal.STL" />
      </geometry>
    </collision>
  </link>
  <joint
    name="r_middle_mcp_pitch"
    type="revolute">
    <origin
      xyz="-0.00052576 -0.1027 -0.00634"
      rpy="-1.5707963267948966 0 3.141592653589793" />
    <parent
      link="r_hand_base_link" />
    <child
      link="r_middle_proximal" />
    <axis
      xyz="0 1 0" />
    <limit
      lower="0"
      upper="1.57"
      effort="100"
      velocity="12" />
  </joint>
  <link
    name="r_middle_distal">
    <inertial>
      <origin
        xyz="0.00658940304809306 -4.5885743593238E-06 0.0194434523296449"
        rpy="0 0 0" />
      <mass
        value="0.00376786259758948" />
      <inertia
        ixx="3.221153658306E-07"
        ixy="1.02639617308432E-11"
        ixz="-1.14363547272711E-07"
        iyy="3.65130723083104E-07"
        iyz="-1.96904618797577E-10"
        izz="1.24256787913797E-07" />
    </inertial>
    <visual>
      <origin
        xyz="0 0 0"
        rpy="0 0 0" />
      <geometry>
        <mesh
          filename="package://x200-11-03/right_hand_meshes/middle_distal.STL" />
      </geometry>
      <material
        name="">
        <color
          rgba="0.164705882352941 0.282352941176471 0.443137254901961 1" />
      </material>
    </visual>
    <collision>
      <origin
        xyz="0 0 0"
        rpy="0 0 0" />
      <geometry>
        <mesh
          filename="package://x200-11-03/right_hand_meshes/middle_distal.STL" />
      </geometry>
    </collision>
  </link>
  <joint
    name="r_middle_dip"
    type="revolute">
    <origin
      xyz="-0.0052516 0 0.036625"
      rpy="0 0 0" />
    <parent
      link="r_middle_proximal" />
    <child
      link="r_middle_distal" />
    <axis
      xyz="0 1 0" />
    <limit
      lower="0"
      upper="1.4"
      effort="100"
      velocity="12" />
    <mimic
      joint="r_middle_mcp_pitch"
      multiplier="0.89"
      offset="0" />
  </joint>
  <link
    name="r_ring_proximal">
    <inertial>
      <origin
        xyz="-0.00208654311325356 -4.98538564003281E-06 0.0172736743497407"
        rpy="0 0 0" />
      <mass
        value="0.00253170963529411" />
      <inertia
        ixx="2.6598913795678E-07"
        ixy="-3.62757108675266E-11"
        ixz="4.31050611555507E-08"
        iyy="2.72914417061517E-07"
        iyz="1.75554984053478E-10"
        izz="8.56012458677515E-08" />
    </inertial>
    <visual>
      <origin
        xyz="0 0 0"
        rpy="0 0 0" />
      <geometry>
        <mesh
          filename="package://x200-11-03/right_hand_meshes/ring_proximal.STL" />
      </geometry>
      <material
        name="">
        <color
          rgba="0.980392156862745 0.780392156862745 0.627450980392157 1" />
      </material>
    </visual>
    <collision>
      <origin
        xyz="0 0 0"
        rpy="0 0 0" />
      <geometry>
        <mesh
          filename="package://x200-11-03/right_hand_meshes/ring_proximal.STL" />
      </geometry>
    </collision>
  </link>
  <joint
    name="r_ring_mcp_pitch"
    type="revolute">
    <origin
      xyz="-0.0010258 -0.098767 0.011135"
      rpy="-1.5184363267948966 0 3.141592653589793" />
    <parent
      link="r_hand_base_link" />
    <child
      link="r_ring_proximal" />
    <axis
      xyz="0 1 0" />
    <limit
      lower="0"
      upper="1.57"
      effort="100"
      velocity="12" />
  </joint>
  <link
    name="r_ring_distal">
    <inertial>
      <origin
        xyz="0.00658940273069729 -4.56628863591824E-06 0.0194435005686854"
        rpy="0 0 0" />
      <mass
        value="0.0037678395356105" />
      <inertia
        ixx="3.22112632437858E-07"
        ixy="1.01848408913558E-11"
        ixz="-1.1436348915342E-07"
        iyy="3.65128262095686E-07"
        iyz="-1.96145632992445E-10"
        izz="1.24256284608064E-07" />
    </inertial>
    <visual>
      <origin
        xyz="0 0 0"
        rpy="0 0 0" />
      <geometry>
        <mesh
          filename="package://x200-11-03/right_hand_meshes/ring_distal.STL" />
      </geometry>
      <material
        name="">
        <color
          rgba="0.164705882352941 0.282352941176471 0.443137254901961 1" />
      </material>
    </visual>
    <collision>
      <origin
        xyz="0 0 0"
        rpy="0 0 0" />
      <geometry>
        <mesh
          filename="package://x200-11-03/right_hand_meshes/ring_distal.STL" />
      </geometry>
    </collision>
  </link>
  <joint
    name="r_ring_dip"
    type="revolute">
    <origin
      xyz="-0.0052516 0 0.036625"
      rpy="0 0 0" />
    <parent
      link="r_ring_proximal" />
    <child
      link="r_ring_distal" />
    <axis
      xyz="0 1 0" />
    <limit
      lower="0"
      upper="1.4"
      effort="100"
      velocity="12" />
    <mimic
      joint="r_ring_mcp_pitch"
      multiplier="0.89"
      offset="0" />
  </joint>
  <link
    name="r_pinky_proximal">
    <inertial>
      <origin
        xyz="-0.00208649034130813 -5.02314582560837E-06 0.0172736680793697"
        rpy="0 0 0" />
      <mass
        value="0.00253167400540778" />
      <inertia
        ixx="2.65988718820404E-07"
        ixy="-3.66012295280295E-11"
        ixz="4.31052220484445E-08"
        iyy="2.72913936904813E-07"
        iyz="1.75447396222308E-10"
        izz="8.56006424720129E-08" />
    </inertial>
    <visual>
      <origin
        xyz="0 0 0"
        rpy="0 0 0" />
      <geometry>
        <mesh
          filename="package://x200-11-03/right_hand_meshes/pinky_proximal.STL" />
      </geometry>
      <material
        name="">
        <color
          rgba="0.980392156862745 0.780392156862745 0.627450980392157 1" />
      </material>
    </visual>
    <collision>
      <origin
        xyz="0 0 0"
        rpy="0 0 0" />
      <geometry>
        <mesh
          filename="package://x200-11-03/right_hand_meshes/pinky_proximal.STL" />
      </geometry>
    </collision>
  </link>
  <joint
    name="r_pinky_mcp_pitch"
    type="revolute">
    <origin
      xyz="-0.0024758 -0.092741 0.028372"
      rpy="-1.4835303267948965 0 3.141592653589793" />
    <parent
      link="r_hand_base_link" />
    <child
      link="r_pinky_proximal" />
    <axis
      xyz="0 1 0" />
    <limit
      lower="0"
      upper="1.57"
      effort="100"
      velocity="12" />
  </joint>
  <link
    name="r_pinky_distal">
    <inertial>
      <origin
        xyz="0.00658940431519205 -4.55268314210333E-06 0.0194435341098305"
        rpy="0 0 0" />
      <mass
        value="0.00376782669873412" />
      <inertia
        ixx="3.22111112339498E-07"
        ixy="1.01707985908333E-11"
        ixz="-1.14363524419061E-07"
        iyy="3.65126916899176E-07"
        iyz="-1.95589215866356E-10"
        izz="1.24256004854426E-07" />
    </inertial>
    <visual>
      <origin
        xyz="0 0 0"
        rpy="0 0 0" />
      <geometry>
        <mesh
          filename="package://x200-11-03/right_hand_meshes/pinky_distal.STL" />
      </geometry>
      <material
        name="">
        <color
          rgba="0.164705882352941 0.282352941176471 0.443137254901961 1" />
      </material>
    </visual>
    <collision>
      <origin
        xyz="0 0 0"
        rpy="0 0 0" />
      <geometry>
        <mesh
          filename="package://x200-11-03/right_hand_meshes/pinky_distal.STL" />
      </geometry>
    </collision>
  </link>
  <joint
    name="r_pinky_dip"
    type="revolute">
    <origin
      xyz="-0.0052516 0 0.036625"
      rpy="0 0 0" />
    <parent
      link="r_pinky_proximal" />
    <child
      link="r_pinky_distal" />
    <axis
      xyz="0 1 0" />
    <limit
      lower="0"
      upper="1.4"
      effort="100"
      velocity="12" />
    <mimic
      joint="r_pinky_mcp_pitch"
      multiplier="0.89"
      offset="0" />
  </joint>

<!--  左手-->
<link
    name="l_hand_base_link">
    <inertial>
      <origin
        xyz="-0.00157788568070457 0.00034876725935859 -0.0538452219801211"
        rpy="0 0 0" />
      <mass
        value="0.0672935238166485" />
      <inertia
        ixx="5.22525212160954E-05"
        ixy="-3.06955729584715E-07"
        ixz="3.90341166950521E-07"
        iyy="3.33522349207724E-05"
        iyz="-7.76680063574627E-07"
        izz="2.28469461105385E-05" />
    </inertial>
    <visual>
      <origin
        xyz="0 0 0"
        rpy="-1.5707963267948966 0 3.141592653589793" />
      <geometry>
        <mesh
          filename="package://x200-11-03/left_hand_meshes/l_hand_base_link.STL" />
      </geometry>
      <material
        name="">
        <color
          rgba="1 1 1 1" />
      </material>
    </visual>
    <collision>
      <origin
        xyz="0 0 0"
        rpy="-1.5707963267948966 0 3.141592653589793" />
      <geometry>
        <mesh
          filename="package://x200-11-03/left_hand_meshes/l_hand_base_link.STL" />
      </geometry>
    </collision>
  </link>
  <link
    name="l_thumb_metacarpals_base2">
    <inertial>
      <origin
        xyz="0.00162800681276937 -0.0027668017246415 -0.00184234438641236"
        rpy="0 0 0" />
      <mass
        value="0.00138588296544333" />
      <inertia
        ixx="5.26292160685909E-08"
        ixy="-3.92888681640568E-09"
        ixz="-2.43767371295222E-09"
        iyy="4.82620491570326E-08"
        iyz="3.71869784206147E-09"
        izz="2.88550286112821E-08" />
    </inertial>
    <visual>
      <origin
        xyz="0 0 0"
        rpy="0 0 0" />
      <geometry>
        <mesh
          filename="package://x200-11-03/left_hand_meshes/thumb_metacarpals_base2.STL" />
      </geometry>
      <material
        name="">
        <color
          rgba="1 1 1 1" />
      </material>
    </visual>
    <collision>
      <origin
        xyz="0 0 0"
        rpy="0 0 0" />
      <geometry>
        <mesh
          filename="package://x200-11-03/left_hand_meshes/thumb_metacarpals_base2.STL" />
      </geometry>
    </collision>
  </link>
  <joint
    name="l_thumb_cmc_yaw"
    type="revolute">
    <origin
      xyz="-0.011508 -0.032794 0.022975"
      rpy="-1.5707963267948966 0 3.141592653589793" />
    <parent
      link="l_hand_base_link" />
    <child
      link="l_thumb_metacarpals_base2" />
    <axis
      xyz="0 0 1" />
    <limit
      lower="0"
      upper="1.54"
      effort="100"
      velocity="12" />
  </joint>
  <link
    name="l_thumb_metacarpals">
    <inertial>
      <origin
        xyz="4.24816204999817E-05 1.74183907812875E-05 0.0228341640631254"
        rpy="0 0 0" />
      <mass
        value="0.0123381586619931" />
      <inertia
        ixx="1.10292537368909E-06"
        ixy="-5.99642232777877E-10"
        ixz="-1.14233573940545E-07"
        iyy="1.76757772551884E-06"
        iyz="-4.03963570823777E-10"
        izz="9.36347792411098E-07" />
    </inertial>
    <visual>
      <origin
        xyz="0 0 0"
        rpy="0 0 0" />
      <geometry>
        <mesh
          filename="package://x200-11-03/left_hand_meshes/thumb_metacarpals.STL" />
      </geometry>
      <material
        name="">
        <color
          rgba="1 1 1 1" />
      </material>
    </visual>
    <collision>
      <origin
        xyz="0 0 0"
        rpy="0 0 0" />
      <geometry>
        <mesh
          filename="package://x200-11-03/left_hand_meshes/thumb_metacarpals.STL" />
      </geometry>
    </collision>
  </link>
  <joint
    name="l_thumb_cmc_pitch"
    type="revolute">
    <origin
      xyz="0.0061649 -0.010678 -0.004891"
      rpy="0 -1.1529 2.0944" />
    <parent
      link="l_thumb_metacarpals_base2" />
    <child
      link="l_thumb_metacarpals" />
    <axis
      xyz="0 1 0" />
    <limit
      lower="0"
      upper="0.52"
      effort="100"
      velocity="12" />
  </joint>
  <link
    name="l_thumb_distal">
    <inertial>
      <origin
        xyz="-0.00413725702921841 -5.90704520436747E-08 0.023011401589736"
        rpy="0 0 0" />
      <mass
        value="0.00763332957284057" />
      <inertia
        ixx="1.3057487813702E-06"
        ixy="-1.19781508112714E-11"
        ixz="-7.19551697268541E-08"
        iyy="1.2248908905341E-06"
        iyz="4.55347974652679E-12"
        izz="2.77271910592615E-07" />
    </inertial>
    <visual>
      <origin
        xyz="0 0 0"
        rpy="0 0 0" />
      <geometry>
        <mesh
          filename="package://x200-11-03/left_hand_meshes/thumb_distal.STL" />
      </geometry>
      <material
        name="">
        <color
          rgba="1 1 1 1" />
      </material>
    </visual>
    <collision>
      <origin
        xyz="0 0 0"
        rpy="0 0 0" />
      <geometry>
        <mesh
          filename="package://x200-11-03/left_hand_meshes/thumb_distal.STL" />
      </geometry>
    </collision>
  </link>
  <joint
    name="l_thumb_ip"
    type="revolute">
    <origin
      xyz="0.0037776 0 0.045368"
      rpy="0 0 0" />
    <parent
      link="l_thumb_metacarpals" />
    <child
      link="l_thumb_distal" />
    <axis
      xyz="0 1 0" />
    <limit
      lower="0"
      upper="0.96"
      effort="100"
      velocity="12" />
    <mimic
      joint="l_thumb_cmc_pitch"
      multiplier="1.83"
      offset="0" />
  </joint>
  <link
    name="l_index_proximal">
    <inertial>
      <origin
        xyz="-0.00208656556336452 2.53838713251686E-06 0.0172734941980264"
        rpy="0 0 0" />
      <mass
        value="0.00253174651934627" />
      <inertia
        ixx="2.65988714157799E-07"
        ixy="-1.67174578825824E-11"
        ixz="-4.31047725546034E-08"
        iyy="2.72914069166233E-07"
        iyz="1.8756709532167E-10"
        izz="8.56017305636748E-08" />
    </inertial>
    <visual>
      <origin
        xyz="0 0 0"
        rpy="0 0 0" />
      <geometry>
        <mesh
          filename="package://x200-11-03/left_hand_meshes/index_proximal.STL" />
      </geometry>
      <material
        name="">
        <color
          rgba="1 1 1 1" />
      </material>
    </visual>
    <collision>
      <origin
        xyz="0 0 0"
        rpy="0 0 0" />
      <geometry>
        <mesh
          filename="package://x200-11-03/left_hand_meshes/index_proximal.STL" />
      </geometry>
    </collision>
  </link>
  <joint
    name="l_index_mcp_pitch"
    type="revolute">
    <origin
      xyz="-0.0024758 -0.098779 0.02419"
      rpy="-1.5184363267948966 0 3.141592653589793" />
    <parent
      link="l_hand_base_link" />
    <child
      link="l_index_proximal" />
    <axis
      xyz="0 1 0" />
    <limit
      lower="0"
      upper="1.57"
      effort="100"
      velocity="12" />
  </joint>
  <link
    name="l_index_distal">
    <inertial>
      <origin
        xyz="0.00658986616416549 5.13855642059191E-06 0.0194393600039178"
        rpy="0 0 0" />
      <mass
        value="0.00376951085886838" />
      <inertia
        ixx="3.22347106085043E-07"
        ixy="1.3801788663582E-11"
        ixz="1.14352857317951E-07"
        iyy="3.65328133721509E-07"
        iyz="-2.11505011705634E-10"
        izz="1.24287996386442E-07" />
    </inertial>
    <visual>
      <origin
        xyz="0 0 0"
        rpy="0 0 0" />
      <geometry>
        <mesh
          filename="package://x200-11-03/left_hand_meshes/index_distal.STL" />
      </geometry>
      <material
        name="">
        <color
          rgba="1 1 1 1" />
      </material>
    </visual>
    <collision>
      <origin
        xyz="0 0 0"
        rpy="0 0 0" />
      <geometry>
        <mesh
          filename="package://x200-11-03/left_hand_meshes/index_distal.STL" />
      </geometry>
    </collision>
  </link>
  <joint
    name="l_index_dip"
    type="revolute">
    <origin
      xyz="-0.0052516 0 0.036625"
      rpy="0 0 0" />
    <parent
      link="l_index_proximal" />
    <child
      link="l_index_distal" />
    <axis
      xyz="0 1 0" />
    <limit
      lower="0"
      upper="1.4"
      effort="100"
      velocity="12" />
    <mimic
      joint="l_index_mcp_pitch"
      multiplier="0.89"
      offset="0" />
  </joint>
  <link
    name="l_middle_proximal">
    <inertial>
      <origin
        xyz="-0.00208660654138235 2.56918180119303E-06 0.0172735011723351"
        rpy="0 0 0" />
      <mass
        value="0.00253177375206983" />
      <inertia
        ixx="2.65989021304483E-07"
        ixy="-1.69816046635662E-11"
        ixz="-4.31046683215273E-08"
        iyy="2.72914402745606E-07"
        iyz="1.87484652324395E-10"
        izz="8.5602213431865E-08" />
    </inertial>
    <visual>
      <origin
        xyz="0 0 0"
        rpy="0 0 0" />
      <geometry>
        <mesh
          filename="package://x200-11-03/left_hand_meshes/middle_proximal.STL" />
      </geometry>
      <material
        name="">
        <color
          rgba="1 1 1 1" />
      </material>
    </visual>
    <collision>
      <origin
        xyz="0 0 0"
        rpy="0 0 0" />
      <geometry>
        <mesh
          filename="package://x200-11-03/left_hand_meshes/middle_proximal.STL" />
      </geometry>
    </collision>
  </link>
  <joint
    name="l_middle_mcp_pitch"
    type="revolute">
    <origin
      xyz="-0.00052576 -0.1027 0.00634"
      rpy="-1.5707963267948966 0 3.141592653589793" />
    <parent
      link="l_hand_base_link" />
    <child
      link="l_middle_proximal" />
    <axis
      xyz="0 1 0" />
    <limit
      lower="0"
      upper="1.57"
      effort="100"
      velocity="12" />
  </joint>
  <link
    name="l_middle_distal">
    <inertial>
      <origin
        xyz="0.00658986516319194 5.10862924271716E-06 0.0194393315699782"
        rpy="0 0 0" />
      <mass
        value="0.00376952789210256" />
      <inertia
        ixx="3.22348591068053E-07"
        ixy="1.37122394856588E-11"
        ixz="1.1435291391668E-07"
        iyy="3.65329535087755E-07"
        iyz="-2.10453810291991E-10"
        izz="1.24288425862546E-07" />
    </inertial>
    <visual>
      <origin
        xyz="0 0 0"
        rpy="0 0 0" />
      <geometry>
        <mesh
          filename="package://x200-11-03/left_hand_meshes/middle_distal.STL" />
      </geometry>
      <material
        name="">
        <color
          rgba="1 1 1 1" />
      </material>
    </visual>
    <collision>
      <origin
        xyz="0 0 0"
        rpy="0 0 0" />
      <geometry>
        <mesh
          filename="package://x200-11-03/left_hand_meshes/middle_distal.STL" />
      </geometry>
    </collision>
  </link>
  <joint
    name="l_middle_dip"
    type="revolute">
    <origin
      xyz="-0.0052516 0 0.036625"
      rpy="0 0 0" />
    <parent
      link="l_middle_proximal" />
    <child
      link="l_middle_distal" />
    <axis
      xyz="0 1 0" />
    <limit
      lower="0"
      upper="1.4"
      effort="100"
      velocity="12" />
    <mimic
      joint="l_middle_mcp_pitch"
      multiplier="0.89"
      offset="0" />
  </joint>
  <link
    name="l_ring_proximal">
    <inertial>
      <origin
        xyz="-0.00208667931345812 2.63000419462034E-06 0.0172734926448377"
        rpy="0 0 0" />
      <mass
        value="0.00253182223645066" />
      <inertia
        ixx="2.65989756076584E-07"
        ixy="-1.74912952703656E-11"
        ixz="-4.31043325594253E-08"
        iyy="2.7291510093393E-07"
        iyz="1.87158326740895E-10"
        izz="8.56031522765909E-08" />
    </inertial>
    <visual>
      <origin
        xyz="0 0 0"
        rpy="0 0 0" />
      <geometry>
        <mesh
          filename="package://x200-11-03/left_hand_meshes/ring_proximal.STL" />
      </geometry>
      <material
        name="">
        <color
          rgba="1 1 1 1" />
      </material>
    </visual>
    <collision>
      <origin
        xyz="0 0 0"
        rpy="0 0 0" />
      <geometry>
        <mesh
          filename="package://x200-11-03/left_hand_meshes/ring_proximal.STL" />
      </geometry>
    </collision>
  </link>
  <joint
    name="l_ring_mcp_pitch"
    type="revolute">
    <origin
      xyz="-0.0010258 -0.098767 -0.011135"
      rpy="-1.6231563267948966 0 3.141592653589793" />
    <parent
      link="l_hand_base_link" />
    <child
      link="l_ring_proximal" />
    <axis
      xyz="0 1 0" />
    <limit
      lower="0"
      upper="1.57"
      effort="100"
      velocity="12" />
  </joint>
  <link
    name="l_ring_distal">
    <inertial>
      <origin
        xyz="0.00658986648895491 5.05883528165163E-06 0.019439397215532"
        rpy="0 0 0" />
      <mass
        value="0.00376949588316609" />
      <inertia
        ixx="3.2234524157181E-07"
        ixy="1.35766976056011E-11"
        ixz="1.14353011012842E-07"
        iyy="3.65326570102147E-07"
        iyz="-2.08672149138738E-10"
        izz="1.24287770218135E-07" />
    </inertial>
    <visual>
      <origin
        xyz="0 0 0"
        rpy="0 0 0" />
      <geometry>
        <mesh
          filename="package://x200-11-03/left_hand_meshes/ring_distal.STL" />
      </geometry>
      <material
        name="">
        <color
          rgba="1 1 1 1" />
      </material>
    </visual>
    <collision>
      <origin
        xyz="0 0 0"
        rpy="0 0 0" />
      <geometry>
        <mesh
          filename="package://x200-11-03/left_hand_meshes/ring_distal.STL" />
      </geometry>
    </collision>
  </link>
  <joint
    name="l_ring_dip"
    type="revolute">
    <origin
      xyz="-0.0052516 0 0.036625"
      rpy="0 0 0" />
    <parent
      link="l_ring_proximal" />
    <child
      link="l_ring_distal" />
    <axis
      xyz="0 1 0" />
    <limit
      lower="0"
      upper="1.4"
      effort="100"
      velocity="12" />
    <mimic
      joint="l_ring_mcp_pitch"
      multiplier="0.89"
      offset="0" />
  </joint>
  <link
    name="l_pinky_proximal">
    <inertial>
      <origin
        xyz="-0.00208673599799501 2.68062251165824E-06 0.0172734848131236"
        rpy="0 0 0" />
      <mass
        value="0.00253185993162408" />
      <inertia
        ixx="2.6599033687183E-07"
        ixy="-1.79030790016555E-11"
        ixz="-4.31040829565781E-08"
        iyy="2.72915617381577E-07"
        iyz="1.86906787420486E-10"
        izz="8.56039175034871E-08" />
    </inertial>
    <visual>
      <origin
        xyz="0 0 0"
        rpy="0 0 0" />
      <geometry>
        <mesh
          filename="package://x200-11-03/left_hand_meshes/pinky_proximal.STL" />
      </geometry>
      <material
        name="">
        <color
          rgba="1 1 1 1" />
      </material>
    </visual>
    <collision>
      <origin
        xyz="0 0 0"
        rpy="0 0 0" />
      <geometry>
        <mesh
          filename="package://x200-11-03/left_hand_meshes/pinky_proximal.STL" />
      </geometry>
    </collision>
  </link>
  <joint
    name="l_pinky_mcp_pitch"
    type="revolute">
    <origin
      xyz="-0.0024758 -0.092741 -0.028372"
      rpy="-1.6580623267948966 0 3.141592653589793" />
    <parent
      link="l_hand_base_link" />
    <child
      link="l_pinky_proximal" />
    <axis
      xyz="0 1 0" />
    <limit
      lower="0"
      upper="1.57"
      effort="100"
      velocity="12" />
  </joint>
  <link
    name="l_pinky_distal">
    <inertial>
      <origin
        xyz="0.00658987588903027 5.03087534178825E-06 0.0194394491065091"
        rpy="0 0 0" />
      <mass
        value="0.00376948071276134" />
      <inertia
        ixx="3.22343583730488E-07"
        ixy="1.35768173270357E-11"
        ixz="1.14353289593012E-07"
        iyy="3.65325180884183E-07"
        iyz="-2.0744198062439E-10"
        izz="1.24287567374229E-07" />
    </inertial>
    <visual>
      <origin
        xyz="0 0 0"
        rpy="0 0 0" />
      <geometry>
        <mesh
          filename="package://x200-11-03/left_hand_meshes/pinky_distal.STL" />
      </geometry>
      <material
        name="">
        <color
          rgba="1 1 1 1" />
      </material>
    </visual>
    <collision>
      <origin
        xyz="0 0 0"
        rpy="0 0 0" />
      <geometry>
        <mesh
          filename="package://x200-11-03/left_hand_meshes/pinky_distal.STL" />
      </geometry>
    </collision>
  </link>
  <joint
    name="l_pinky_dip"
    type="revolute">
    <origin
      xyz="-0.0052516 0 0.036625"
      rpy="0 0 0" />
    <parent
      link="l_pinky_proximal" />
    <child
      link="l_pinky_distal" />
    <axis
      xyz="0 1 0" />
    <limit
      lower="0"
      upper="1.4"
      effort="100"
      velocity="12" />
    <mimic
      joint="l_pinky_mcp_pitch"
      multiplier="0.89"
      offset="0" />
  </joint>


<!--  双手与Body链接-->
    <joint name="right_linkerhand_mount_joint" type="fixed">
      <origin xyz="0.02 0 0" rpy="3.1516926 0 -1.5708"/>
      <parent link="right_hand_base_link"/>
      <child link="r_hand_base_link"/>
    </joint>


  <joint name="left_linkerhand_mount_joint" type="fixed">
    <origin xyz="0.02 0 0" rpy="0 0 1.5708"/>
    <parent link="left_hand_base_link"/>
    <child link="l_hand_base_link"/>
  </joint>

</robot>